<mujoco model="cartpole">
  <option timestep="0.01"/>

  <default>
    <default class="pole">
      <joint type="hinge" axis="0 1 0" damping="2e-6"/>
      <geom type="capsule" fromto="0 0 0 0 0 1" size="0.045" material="pole" mass=".1"/>
    </default>
  </default>

  <asset>
    <texture name="grid" type="2d" builtin="checker" rgb1=".1 .2 .3" rgb2=".2 .3 .4" width="300" height="300"/>
    <material name="grid" texture="grid" texrepeat="8 8" reflectance=".2"/>
    <material name="cart" rgba=".7 .1 .1 1"/>
    <material name="pole" rgba=".1 .5 .8 1"/>
    <material name="decoration" rgba=".3 .3 .3 1"/>
  </asset>

  <worldbody>
    <light name="light" pos="0 0 6"/>
    <camera name="fixed" pos="0 -4 1" zaxis="0 -1 0"/>
    <camera name="lookatcart" mode="targetbody" target="cart" pos="0 -2 2"/>
    <geom name="floor" pos="0 0 -.05" size="4 4 .2" type="plane" material="grid"/>
    <geom name="rail1" type="capsule" pos="0 .07 1" zaxis="1 0 0" size="0.02 2" material="decoration"/>
    <geom name="rail2" type="capsule" pos="0 -.07 1" zaxis="1 0 0" size="0.02 2" material="decoration"/>
    <body name="sphere" pos="0 0 0.2">
      <joint name="tx" type="slide" axis="1 0 0" range="-2 2" damping="1"/>
      <joint name="ty" type="slide" axis="0 1 0" range="-2 2" damping="1"/>
      <joint name="tz" type="slide" axis="0 0 1" range="0.05 2" damping="1"/>
      <geom name="sphere_geom" type="sphere" size="0.07" mass="1.0" rgba="0.2 0.6 0.9 1"/>
    </body>
  </worldbody>
</mujoco>
